{"author":{"id":"f1c91e26662d64f030f6a4ed6dbff696c557d3851901ee72d5fa252916fa4858"},"ops":[{"type":1,"author":{"id":"f1c91e26662d64f030f6a4ed6dbff696c557d3851901ee72d5fa252916fa4858"},"timestamp":1385561021,"nonce":"SmWK1YmhW2jfGfQrBE9i/mg0I5A=","title":"AttributeError generated for unknown reasons","message":"Error of unknown cause generated:\n\nTraceback (most recent call last):\n  File \"ged2dot.py\", line 644, in \u003cmodule\u003e\n    main()\n  File \"ged2dot.py\", line 641, in main\n    model.save()\n  File \"ged2dot.py\", line 175, in save\n    layout.calc()\n  File \"ged2dot.py\", line 517, in calc\n    siblingFamilies = self.__filterFamilies()\n  File \"ged2dot.py\", line 334, in __filterFamilies\n    indiFamily = getattr(pending, indi).famc\nAttributeError: 'NoneType' object has no attribute 'husb'","files":null}]}