{"version":2,"ops":[{"type":1,"author":{"id":"c86ffe22259f983bad14890d610086fc9c8efc89"},"timestamp":1452804957,"metadata":{"github-id":"MDU6SXNzdWUxMjY3NDYyMTU=","github-url":"https://github.com/vmiklos/ged2dot/issues/5","origin":"github"},"title":"Configuration invalid? File contains no section headers.","message":"Rename the attached file from `.ged.txt` to `.ged`.\n\n```\n./ged2dot.py ../My-Family-14-Jan-2016.ged \nConfiguration invalid? File contains no section headers.\nfile: '../My-Family-14-Jan-2016.ged', line: 1\n'0 HEAD\\n'\nTraceback (most recent call last):\n  File \"./ged2dot.py\", line 873, in main\n    config = Config(sys.argv[1:])\n  File \"./ged2dot.py\", line 816, in __init__\n    self.parse()\n  File \"./ged2dot.py\", line 834, in parse\n    self.parser.read(path)\n  File \"/usr/lib/python3.4/configparser.py\", line 672, in read\n    self._read(fp, filename)\n  File \"/usr/lib/python3.4/configparser.py\", line 1058, in _read\n    raise MissingSectionHeaderError(fpname, lineno, line)\nconfigparser.MissingSectionHeaderError: File contains no section headers.\nfile: '../My-Family-14-Jan-2016.ged', line: 1\n'0 HEAD\\n'\n\nDuring handling of the above exception, another exception occurred:\n\nTraceback (most recent call last):\n  File \"./ged2dot.py\", line 889, in \u003cmodule\u003e\n    main()\n  File \"./ged2dot.py\", line 876, in main\n    config.usage()\nUnboundLocalError: local variable 'config' referenced before assignment\n```\n\n[My-Family-14-Jan-2016.ged.txt](https://github.com/vmiklos/ged2dot/files/90997/My-Family-14-Jan-2016.ged.txt)\n\nFile loads fine using LibreOffice extension.","files":null}]}