{"version":2,"ops":[{"type":1,"author":{"id":"9d25bee7ecdb57f6a925492f8ebc60cd8cbf874c"},"timestamp":1385561021,"metadata":{"github-id":"MDU6SXNzdWUyMzM4ODQyMQ==","github-url":"https://github.com/vmiklos/ged2dot/issues/2","origin":"github"},"title":"AttributeError generated for unknown reasons","message":"Error of unknown cause generated:\n\nTraceback (most recent call last):\n  File \"ged2dot.py\", line 644, in \u003cmodule\u003e\n    main()\n  File \"ged2dot.py\", line 641, in main\n    model.save()\n  File \"ged2dot.py\", line 175, in save\n    layout.calc()\n  File \"ged2dot.py\", line 517, in calc\n    siblingFamilies = self.__filterFamilies()\n  File \"ged2dot.py\", line 334, in __filterFamilies\n    indiFamily = getattr(pending, indi).famc\nAttributeError: 'NoneType' object has no attribute 'husb'","files":null}]}